[2022-09-09 01:07:46,878] {taskinstance.py:1179} INFO - Dependencies all met for <TaskInstance: example3.t1 manual__2022-09-08T17:07:36.033114+00:00 [queued]>
[2022-09-09 01:07:46,886] {taskinstance.py:1179} INFO - Dependencies all met for <TaskInstance: example3.t1 manual__2022-09-08T17:07:36.033114+00:00 [queued]>
[2022-09-09 01:07:46,886] {taskinstance.py:1376} INFO - 
--------------------------------------------------------------------------------
[2022-09-09 01:07:46,886] {taskinstance.py:1377} INFO - Starting attempt 1 of 2
[2022-09-09 01:07:46,886] {taskinstance.py:1378} INFO - 
--------------------------------------------------------------------------------
[2022-09-09 01:07:46,904] {taskinstance.py:1397} INFO - Executing <Task(PythonOperator): t1> on 2022-09-08 17:07:36.033114+00:00
[2022-09-09 01:07:46,907] {standard_task_runner.py:52} INFO - Started process 18211 to run task
[2022-09-09 01:07:46,912] {standard_task_runner.py:79} INFO - Running: ['airflow', 'tasks', 'run', 'example3', 't1', 'manual__2022-09-08T17:07:36.033114+00:00', '--job-id', '48', '--raw', '--subdir', 'DAGS_FOLDER/example3.py', '--cfg-path', '/var/folders/ll/lb_b4vvx7cgfp2wpfsv4w6zm0000gn/T/tmpakg1gbef', '--error-file', '/var/folders/ll/lb_b4vvx7cgfp2wpfsv4w6zm0000gn/T/tmpwo74tv8y']
[2022-09-09 01:07:46,914] {standard_task_runner.py:80} INFO - Job 48: Subtask t1
[2022-09-09 01:07:46,967] {task_command.py:371} INFO - Running <TaskInstance: example3.t1 manual__2022-09-08T17:07:36.033114+00:00 [running]> on host 1.0.0.0.0.0.0.0.0.0.0.0.0.0.0.0.0.0.0.0.0.0.0.0.0.0.0.0.0.0.0.0.ip6.arpa
[2022-09-09 01:07:47,033] {taskinstance.py:1591} INFO - Exporting the following env vars:
AIRFLOW_CTX_DAG_EMAIL=airflow@example.com
AIRFLOW_CTX_DAG_OWNER=airflow
AIRFLOW_CTX_DAG_ID=example3
AIRFLOW_CTX_TASK_ID=t1
AIRFLOW_CTX_EXECUTION_DATE=2022-09-08T17:07:36.033114+00:00
AIRFLOW_CTX_TRY_NUMBER=1
AIRFLOW_CTX_DAG_RUN_ID=manual__2022-09-08T17:07:36.033114+00:00
[2022-09-09 01:07:47,034] {taskinstance.py:1909} ERROR - Task failed with exception
Traceback (most recent call last):
  File "/opt/anaconda3/lib/python3.7/site-packages/airflow/operators/python.py", line 171, in execute
    return_value = self.execute_callable()
  File "/opt/anaconda3/lib/python3.7/site-packages/airflow/operators/python.py", line 189, in execute_callable
    return self.python_callable(*self.op_args, **self.op_kwargs)
  File "/Users/chunweichang/airflow/tasks/test.py", line 5, in extract
    data = json.loads(response)
NameError: name 'json' is not defined
[2022-09-09 01:07:47,039] {taskinstance.py:1420} INFO - Marking task as UP_FOR_RETRY. dag_id=example3, task_id=t1, execution_date=20220908T170736, start_date=20220908T170746, end_date=20220908T170747
[2022-09-09 01:07:47,048] {standard_task_runner.py:97} ERROR - Failed to execute job 48 for task t1 (name 'json' is not defined; 18211)
[2022-09-09 01:07:47,100] {local_task_job.py:156} INFO - Task exited with return code 1
[2022-09-09 01:07:47,142] {local_task_job.py:273} INFO - 0 downstream tasks scheduled from follow-on schedule check
