[2022-09-07 17:40:13,799] {taskinstance.py:1179} INFO - Dependencies all met for <TaskInstance: example2.t1 manual__2022-09-07T09:39:24.256218+00:00 [queued]>
[2022-09-07 17:40:13,808] {taskinstance.py:1179} INFO - Dependencies all met for <TaskInstance: example2.t1 manual__2022-09-07T09:39:24.256218+00:00 [queued]>
[2022-09-07 17:40:13,809] {taskinstance.py:1376} INFO - 
--------------------------------------------------------------------------------
[2022-09-07 17:40:13,809] {taskinstance.py:1377} INFO - Starting attempt 1 of 2
[2022-09-07 17:40:13,809] {taskinstance.py:1378} INFO - 
--------------------------------------------------------------------------------
[2022-09-07 17:40:13,822] {taskinstance.py:1397} INFO - Executing <Task(PythonOperator): t1> on 2022-09-07 09:39:24.256218+00:00
[2022-09-07 17:40:13,823] {standard_task_runner.py:52} INFO - Started process 8655 to run task
[2022-09-07 17:40:13,829] {standard_task_runner.py:79} INFO - Running: ['airflow', 'tasks', 'run', 'example2', 't1', 'manual__2022-09-07T09:39:24.256218+00:00', '--job-id', '13', '--raw', '--subdir', 'DAGS_FOLDER/example2.py', '--cfg-path', '/var/folders/ll/lb_b4vvx7cgfp2wpfsv4w6zm0000gn/T/tmpujvhaglx', '--error-file', '/var/folders/ll/lb_b4vvx7cgfp2wpfsv4w6zm0000gn/T/tmprhjtlnnc']
[2022-09-07 17:40:13,830] {standard_task_runner.py:80} INFO - Job 13: Subtask t1
[2022-09-07 17:40:13,881] {task_command.py:371} INFO - Running <TaskInstance: example2.t1 manual__2022-09-07T09:39:24.256218+00:00 [running]> on host 1.0.0.127.in-addr.arpa
[2022-09-07 17:40:13,944] {taskinstance.py:1591} INFO - Exporting the following env vars:
AIRFLOW_CTX_DAG_EMAIL=airflow@example.com
AIRFLOW_CTX_DAG_OWNER=airflow
AIRFLOW_CTX_DAG_ID=example2
AIRFLOW_CTX_TASK_ID=t1
AIRFLOW_CTX_EXECUTION_DATE=2022-09-07T09:39:24.256218+00:00
AIRFLOW_CTX_TRY_NUMBER=1
AIRFLOW_CTX_DAG_RUN_ID=manual__2022-09-07T09:39:24.256218+00:00
[2022-09-07 17:40:13,950] {base.py:68} INFO - Using connection ID 'mongo_default' for task execution.
[2022-09-07 17:40:44,324] {taskinstance.py:1909} ERROR - Task failed with exception
Traceback (most recent call last):
  File "/opt/anaconda3/lib/python3.7/site-packages/airflow/operators/python.py", line 171, in execute
    return_value = self.execute_callable()
  File "/opt/anaconda3/lib/python3.7/site-packages/airflow/operators/python.py", line 189, in execute_callable
    return self.python_callable(*self.op_args, **self.op_kwargs)
  File "/Users/chunweichang/airflow/tasks/f.py", line 6, in extract
    documents = list(collections.find())
  File "/opt/anaconda3/lib/python3.7/site-packages/pymongo/cursor.py", line 1238, in next
    if len(self.__data) or self._refresh():
  File "/opt/anaconda3/lib/python3.7/site-packages/pymongo/cursor.py", line 1130, in _refresh
    self.__session = self.__collection.database.client._ensure_session()
  File "/opt/anaconda3/lib/python3.7/site-packages/pymongo/mongo_client.py", line 1935, in _ensure_session
    return self.__start_session(True, causal_consistency=False)
  File "/opt/anaconda3/lib/python3.7/site-packages/pymongo/mongo_client.py", line 1883, in __start_session
    server_session = self._get_server_session()
  File "/opt/anaconda3/lib/python3.7/site-packages/pymongo/mongo_client.py", line 1921, in _get_server_session
    return self._topology.get_server_session()
  File "/opt/anaconda3/lib/python3.7/site-packages/pymongo/topology.py", line 520, in get_server_session
    session_timeout = self._check_session_support()
  File "/opt/anaconda3/lib/python3.7/site-packages/pymongo/topology.py", line 502, in _check_session_support
    None)
  File "/opt/anaconda3/lib/python3.7/site-packages/pymongo/topology.py", line 220, in _select_servers_loop
    (self._error_message(selector), timeout, self.description))
pymongo.errors.ServerSelectionTimeoutError: mongo:27017: [Errno 8] nodename nor servname provided, or not known, Timeout: 30s, Topology Description: <TopologyDescription id: 631866fd1e9fefec0ac80ad1, topology_type: Single, servers: [<ServerDescription ('mongo', 27017) server_type: Unknown, rtt: None, error=AutoReconnect('mongo:27017: [Errno 8] nodename nor servname provided, or not known')>]>
[2022-09-07 17:40:44,333] {taskinstance.py:1420} INFO - Marking task as UP_FOR_RETRY. dag_id=example2, task_id=t1, execution_date=20220907T093924, start_date=20220907T094013, end_date=20220907T094044
[2022-09-07 17:40:44,344] {standard_task_runner.py:97} ERROR - Failed to execute job 13 for task t1 (mongo:27017: [Errno 8] nodename nor servname provided, or not known, Timeout: 30s, Topology Description: <TopologyDescription id: 631866fd1e9fefec0ac80ad1, topology_type: Single, servers: [<ServerDescription ('mongo', 27017) server_type: Unknown, rtt: None, error=AutoReconnect('mongo:27017: [Errno 8] nodename nor servname provided, or not known')>]>; 8655)
[2022-09-07 17:40:44,369] {local_task_job.py:156} INFO - Task exited with return code 1
[2022-09-07 17:40:44,398] {local_task_job.py:273} INFO - 0 downstream tasks scheduled from follow-on schedule check
