[2022-09-11 00:17:36,855] {taskinstance.py:1179} INFO - Dependencies all met for <TaskInstance: example3.t1 manual__2022-09-10T16:12:25.170012+00:00 [queued]>
[2022-09-11 00:17:36,864] {taskinstance.py:1179} INFO - Dependencies all met for <TaskInstance: example3.t1 manual__2022-09-10T16:12:25.170012+00:00 [queued]>
[2022-09-11 00:17:36,864] {taskinstance.py:1376} INFO - 
--------------------------------------------------------------------------------
[2022-09-11 00:17:36,864] {taskinstance.py:1377} INFO - Starting attempt 2 of 2
[2022-09-11 00:17:36,864] {taskinstance.py:1378} INFO - 
--------------------------------------------------------------------------------
[2022-09-11 00:17:36,876] {taskinstance.py:1397} INFO - Executing <Task(PythonOperator): t1> on 2022-09-10 16:12:25.170012+00:00
[2022-09-11 00:17:36,878] {standard_task_runner.py:52} INFO - Started process 28446 to run task
[2022-09-11 00:17:36,883] {standard_task_runner.py:79} INFO - Running: ['airflow', 'tasks', 'run', 'example3', 't1', 'manual__2022-09-10T16:12:25.170012+00:00', '--job-id', '71', '--raw', '--subdir', 'DAGS_FOLDER/example3.py', '--cfg-path', '/var/folders/ll/lb_b4vvx7cgfp2wpfsv4w6zm0000gn/T/tmpvza3ciuu', '--error-file', '/var/folders/ll/lb_b4vvx7cgfp2wpfsv4w6zm0000gn/T/tmp89i38sd7']
[2022-09-11 00:17:36,885] {standard_task_runner.py:80} INFO - Job 71: Subtask t1
[2022-09-11 00:17:36,936] {task_command.py:371} INFO - Running <TaskInstance: example3.t1 manual__2022-09-10T16:12:25.170012+00:00 [running]> on host 1.0.0.0.0.0.0.0.0.0.0.0.0.0.0.0.0.0.0.0.0.0.0.0.0.0.0.0.0.0.0.0.ip6.arpa
[2022-09-11 00:17:36,994] {taskinstance.py:1591} INFO - Exporting the following env vars:
AIRFLOW_CTX_DAG_EMAIL=airflow@example.com
AIRFLOW_CTX_DAG_OWNER=airflow
AIRFLOW_CTX_DAG_ID=example3
AIRFLOW_CTX_TASK_ID=t1
AIRFLOW_CTX_EXECUTION_DATE=2022-09-10T16:12:25.170012+00:00
AIRFLOW_CTX_TRY_NUMBER=2
AIRFLOW_CTX_DAG_RUN_ID=manual__2022-09-10T16:12:25.170012+00:00
[2022-09-11 00:17:36,995] {taskinstance.py:1909} ERROR - Task failed with exception
Traceback (most recent call last):
  File "/opt/anaconda3/lib/python3.7/site-packages/airflow/operators/python.py", line 171, in execute
    return_value = self.execute_callable()
  File "/opt/anaconda3/lib/python3.7/site-packages/airflow/operators/python.py", line 189, in execute_callable
    return self.python_callable(*self.op_args, **self.op_kwargs)
  File "/Users/chunweichang/airflow/tasks/test.py", line 12, in extract
    print(url)
NameError: name 'url' is not defined
[2022-09-11 00:17:36,999] {taskinstance.py:1420} INFO - Marking task as FAILED. dag_id=example3, task_id=t1, execution_date=20220910T161225, start_date=20220910T161736, end_date=20220910T161736
[2022-09-11 00:17:37,008] {standard_task_runner.py:97} ERROR - Failed to execute job 71 for task t1 (name 'url' is not defined; 28446)
[2022-09-11 00:17:37,029] {local_task_job.py:156} INFO - Task exited with return code 1
[2022-09-11 00:17:37,055] {local_task_job.py:273} INFO - 0 downstream tasks scheduled from follow-on schedule check
