[2022-09-12 10:53:26,663] {taskinstance.py:1179} INFO - Dependencies all met for <TaskInstance: example3.t1 manual__2022-09-12T02:53:19.013587+00:00 [queued]>
[2022-09-12 10:53:26,673] {taskinstance.py:1179} INFO - Dependencies all met for <TaskInstance: example3.t1 manual__2022-09-12T02:53:19.013587+00:00 [queued]>
[2022-09-12 10:53:26,673] {taskinstance.py:1376} INFO - 
--------------------------------------------------------------------------------
[2022-09-12 10:53:26,673] {taskinstance.py:1377} INFO - Starting attempt 1 of 2
[2022-09-12 10:53:26,673] {taskinstance.py:1378} INFO - 
--------------------------------------------------------------------------------
[2022-09-12 10:53:26,687] {taskinstance.py:1397} INFO - Executing <Task(PythonOperator): t1> on 2022-09-12 02:53:19.013587+00:00
[2022-09-12 10:53:26,691] {standard_task_runner.py:52} INFO - Started process 31566 to run task
[2022-09-12 10:53:26,698] {standard_task_runner.py:79} INFO - Running: ['airflow', 'tasks', 'run', 'example3', 't1', 'manual__2022-09-12T02:53:19.013587+00:00', '--job-id', '90', '--raw', '--subdir', 'DAGS_FOLDER/example3.py', '--cfg-path', '/var/folders/ll/lb_b4vvx7cgfp2wpfsv4w6zm0000gn/T/tmpyaahwwle', '--error-file', '/var/folders/ll/lb_b4vvx7cgfp2wpfsv4w6zm0000gn/T/tmpzaz318sr']
[2022-09-12 10:53:26,699] {standard_task_runner.py:80} INFO - Job 90: Subtask t1
[2022-09-12 10:53:26,766] {task_command.py:371} INFO - Running <TaskInstance: example3.t1 manual__2022-09-12T02:53:19.013587+00:00 [running]> on host 1.0.0.0.0.0.0.0.0.0.0.0.0.0.0.0.0.0.0.0.0.0.0.0.0.0.0.0.0.0.0.0.ip6.arpa
[2022-09-12 10:53:26,844] {taskinstance.py:1591} INFO - Exporting the following env vars:
AIRFLOW_CTX_DAG_EMAIL=airflow@example.com
AIRFLOW_CTX_DAG_OWNER=airflow
AIRFLOW_CTX_DAG_ID=example3
AIRFLOW_CTX_TASK_ID=t1
AIRFLOW_CTX_EXECUTION_DATE=2022-09-12T02:53:19.013587+00:00
AIRFLOW_CTX_TRY_NUMBER=1
AIRFLOW_CTX_DAG_RUN_ID=manual__2022-09-12T02:53:19.013587+00:00
[2022-09-12 10:53:26,846] {logging_mixin.py:115} INFO - done
[2022-09-12 10:53:26,847] {taskinstance.py:1909} ERROR - Task failed with exception
Traceback (most recent call last):
  File "/opt/anaconda3/lib/python3.7/site-packages/airflow/operators/python.py", line 171, in execute
    return_value = self.execute_callable()
  File "/opt/anaconda3/lib/python3.7/site-packages/airflow/operators/python.py", line 189, in execute_callable
    return self.python_callable(*self.op_args, **self.op_kwargs)
  File "/Users/chunweichang/airflow/tasks/test.py", line 8, in extract
    return documents
NameError: name 'documents' is not defined
[2022-09-12 10:53:26,853] {taskinstance.py:1420} INFO - Marking task as UP_FOR_RETRY. dag_id=example3, task_id=t1, execution_date=20220912T025319, start_date=20220912T025326, end_date=20220912T025326
[2022-09-12 10:53:26,864] {standard_task_runner.py:97} ERROR - Failed to execute job 90 for task t1 (name 'documents' is not defined; 31566)
[2022-09-12 10:53:26,882] {local_task_job.py:156} INFO - Task exited with return code 1
[2022-09-12 10:53:26,919] {local_task_job.py:273} INFO - 0 downstream tasks scheduled from follow-on schedule check
